#VRML_SIM R2025a utf8

EXTERNPROTO "https://raw.githubusercontent.com/cyberbotics/webots/R2025a/projects/objects/backgrounds/protos/TexturedBackground.proto"
EXTERNPROTO "https://raw.githubusercontent.com/cyberbotics/webots/R2025a/projects/objects/backgrounds/protos/TexturedBackgroundLight.proto"
EXTERNPROTO "../protos/RectangleArena.proto"
EXTERNPROTO "https://raw.githubusercontent.com/cyberbotics/webots/R2025a/projects/appearances/protos/Parquetry.proto"
IMPORTABLE EXTERNPROTO "../protos/Robot_.proto"
EXTERNPROTO "../protos/Pioneer3Gripper.proto"

WorldInfo {
}
Viewpoint {
  orientation -0.006020313431450681 0.9999015113982869 0.012677670511916905 0.8871246361135552
  position -2.56940023978105 -0.7630515195812014 3.203336179012431
}
TexturedBackground {
}
TexturedBackgroundLight {
}
RectangleArena {
  floorSize 3 3
  floorAppearance Parquetry {
  }
  wallHeight 0.4
}
Group {
  children [
    Solid {
      translation 0.364901 0.963335 0.0496076
      rotation 0.004217096073893011 0.9999822159425671 -0.004217096073893121 1.570814111010466
      children [
        Shape {
          appearance PBRAppearance {
            baseColor 0.666667 0.333333 1
            roughness 1
            metalness 0
          }
          geometry Box {
            size 0.1 0.1 0.1
          }
        }
      ]
      name "Box3"
      boundingObject Box {
        size 0.1 0.1 0.1
      }
      physics Physics {
      }
      linearVelocity 1.845701661890756e-16 6.755379635726281e-17 0
      angularVelocity -1.3322676295501855e-15 3.996802888650563e-15 1.0891178975741817e-17
    }
    Solid {
      translation 0.5980277401015376 -0.38402088139933593 0.03486538205956404
      rotation -0.6433651148260818 -0.7655594875806354 3.1256834738281557e-07 -3.1415924359549123
      children [
        Shape {
          appearance PBRAppearance {
            baseColor 0.333333 0.666667 1
            roughness 1
            metalness 0
          }
          geometry Box {
            size 0.07 0.07 0.07
          }
        }
      ]
      name "Box2"
      boundingObject Box {
        size 0.07 0.07 0.07
      }
      physics Physics {
      }
      linearVelocity -6.419633830330776e-08 -1.685709646579038e-07 1.9344687772794936e-07
      angularVelocity 4.816281121399261e-06 -1.834168848120107e-06 4.423042999764416e-16
    }
    Solid {
      translation 0.43000000197044674 0.5573143906032518 0.0496076
      rotation -4.884886730897261e-17 -1.0922152224127514e-17 -0.9999999999999999 1.570795332452236
      children [
        Shape {
          appearance PBRAppearance {
            baseColor 0.666667 0 1
            roughness 1
            metalness 0
          }
          geometry Box {
            size 0.1 0.1 0.1
          }
        }
      ]
      name "Box1"
      boundingObject Box {
        size 0.1 0.1 0.1
      }
      physics Physics {
      }
      linearVelocity -6.913907848471434e-17 4.0950728838028357e-17 -2.5569758980472698e-17
      angularVelocity -1.1627824385817652e-15 -1.7461050968701139e-15 7.333294701693942e-17
    }
  ]
}
Robot {
  translation -0.86 0 0
  rotation 0 1 0 0
  children [
    HingeJoint {
      jointParameters HingeJointParameters {
      }
      device [
        PositionSensor {
        }
        RotationalMotor {
        }
      ]
      endPoint Solid {
        translation 0.9743 -0.23 0.157
        children [
          DEF base_grip Solid {
            translation -0.03400000000000003 -0.010000000000000009 0.09994551347543337
            children [
              Shape {
                appearance PBRAppearance {
                  baseColor 0.333333 0 1
                  roughness 1
                  metalness 0
                }
                geometry Cylinder {
                  height 0.1
                  radius 0.011
                }
              }
            ]
            name "base_grip"
            boundingObject Cylinder {
              height 0.1
              radius 0.011
            }
            physics Physics {
            }
            linearVelocity 0 0 -4.616332556850332e-09
          }
          DEF gripper Solid {
            translation 0.05999535759549854 -0.16997765221837216 -0.04052493706512797
            rotation -2.484086015598447e-06 -8.81310243463603e-06 -0.9999999999580794 1.7017011968891362
            children [
              DEF GRIPPER_BASE Pioneer3Gripper {
                hidden position_0_0 0.05000793130882717
                hidden translation_1 0.0425 0 -0.06603567939023583
                hidden position_1_0 0.03999999671453056
                hidden position_1_1 0.039999996722212064
                hidden translation_2 -0.06199999671453056 0 -0.02
                translation -0.17 -0.11 0.01
              }
            ]
            physics Physics {
            }
            linearVelocity -1.5946923685687326e-15 4.6900898156050876e-15 4.117326401157582e-10
            angularVelocity 1.860054769900013e-11 2.4229862267243197e-11 6.6735008602122e-16
          }
        ]
        name "gripper"
      }
    }
    Solid {
      translation 0.94 -0.24 0.3099858234798584
      rotation 0 1 0 1.5707996938995745
      children [
        Shape {
          appearance PBRAppearance {
            baseColor 0.666667 1 0
            roughness 1
            metalness 0
          }
          geometry Cylinder {
            height 0.04
            radius 0.024
          }
        }
      ]
      name "link3-gripper"
      boundingObject Cylinder {
        height 0.04
        radius 0.024
      }
      physics Physics {
      }
      linearVelocity 0 0 -8.78998357988797e-09
    }
    Solid {
      translation 0.941 0 0.3129701430165308
      rotation 0 1 0 1.5707996938995745
      children [
        Shape {
          appearance PBRAppearance {
            baseColor 0.666667 1 0
            roughness 1
            metalness 0
          }
          geometry Cylinder {
            height 0.04
            radius 0.024
          }
        }
      ]
      name "link2-3"
      boundingObject Cylinder {
        height 0.04
        radius 0.024
      }
      physics Physics {
      }
      linearVelocity 0 0 -8.78998357988797e-09
    }
    Solid {
      translation 0.941 0 0.089
      rotation 0 1 0 1.5707996938995747
      children [
        Shape {
          appearance PBRAppearance {
            baseColor 0.666667 1 0
            roughness 1
            metalness 0
          }
          geometry Cylinder {
            height 0.024
            radius 0.026
          }
        }
      ]
      name "link1-2"
    }
    HingeJoint {
      jointParameters HingeJointParameters {
        position 1.2148639461856545e-05
      }
      device [
        RotationalMotor {
          name "wrist motor"
        }
        PositionSensor {
          name "wrist sensor"
        }
      ]
      endPoint Solid {
        translation 0.9429999999999997 -0.12000376606937785 0.3099985421403887
        rotation 1 0 0 1.5708124547398854
        children [
          Shape {
            appearance PBRAppearance {
              baseColor 0 0.333333 0
            }
            geometry Cylinder {
              height 0.2
              radius 0.01
            }
          }
        ]
        name "wrist"
        boundingObject Cylinder {
          height 0.2
          radius 0.01
        }
        physics Physics {
        }
        linearVelocity 2.2289400727824437e-09 -3.1090059861210695e-06 -1.217939873724131e-06
        angularVelocity 1.0029875616513891e-05 7.148268316029318e-09 1.114092026448299e-10
      }
    }
    HingeJoint {
      jointParameters HingeJointParameters {
        position 6.080816639737161e-06
        axis 0 0 1
      }
      device [
        PositionSensor {
          name "elbow sensor"
        }
        RotationalMotor {
          name "elbow motor"
        }
      ]
      endPoint Solid {
        translation 0.9399999999826204 5.715967641317703e-06 0.1999999999999996
        rotation 0 0 1 0.1309057747161997
        children [
          Shape {
            appearance PBRAppearance {
              baseColor 0 0.333333 0
            }
            geometry Cylinder {
              height 0.2
              radius 0.01
            }
          }
        ]
        name "elbow"
        boundingObject Cylinder {
          height 0.2
          radius 0.01
        }
        physics Physics {
        }
        linearVelocity 1.3890888207997442e-09 8.822023616028398e-06 -1.4371974305054925e-08
        angularVelocity 8.65349323472355e-11 7.1722606090640954e-09 9.385557236077203e-06
      }
    }
    HingeJoint {
      jointParameters HingeJointParameters {
        position -4.4739575079229435e-05
        axis 0 0 1
      }
      device [
        PositionSensor {
          name "shoulder_ sensor"
        }
        RotationalMotor {
          name "shoulder_motor"
        }
      ]
      endPoint Solid {
        translation 0.9999999989991837 -4.473957506430404e-05 0.07499999999999984
        rotation 0.9999999997497965 -2.2369787537749053e-05 -1.369709188062781e-21 3.141592653589793
        children [
          Shape {
            appearance PBRAppearance {
              baseColor 0 0.666667 0
            }
            geometry Cylinder {
              height 0.08
              radius 0.05
            }
          }
        ]
        name "shoulder"
        boundingObject Cylinder {
          height 0.08
          radius 0.05
        }
        physics Physics {
        }
        linearVelocity 1.1182882978082555e-08 9.976601489865399e-05 -1.5253008565206343e-07
        angularVelocity 4.3578686071161375e-09 7.626492067448734e-08 9.980976348275531e-05
      }
    }
    Solid {
      translation 1 0 0.00984925153875768
      children [
        Shape {
          appearance PBRAppearance {
            baseColor 0 0 0.498039
            roughness 1
            metalness 0
          }
          geometry Cylinder {
            height 0.05
            radius 0.07
          }
        }
      ]
      name "base"
      boundingObject Cylinder {
        height 0.05
        radius 0.07
      }
      physics Physics {
      }
      linearVelocity 0 0 -9.344314592852559e-08
    }
  ]
  name "RRR"
  controller "gripper_controller"
}
Robot {
  translation 1.2342380502574706 -0.4631521217646051 -0.01051956153915188
  rotation 0.00029889206330149874 -0.0006633592137259034 0.9999997353090089 3.02640107547134
  children [
    GPS {
      translation -0.07 -0.02 0.09
      children [
        DEF shape Shape {
          appearance PBRAppearance {
            baseColor 0 0 1
            roughness 1
            metalness 0
          }
          geometry Box {
            size 0.02 0.02 0.02
          }
        }
      ]
      boundingObject USE shape
      physics Physics {
      }
      accuracy 1
    }
    DistanceSensor {
      translation -0.094 -0.025 0.05
      rotation 0.03012997046226688 -0.999543971098774 0.0020086612547790114 3.141592653589793
      children [
        DEF shape Shape {
          appearance PBRAppearance {
          }
          geometry Box {
            size 0.01 0.01 0.01
          }
        }
      ]
      name "mid_sensor"
      boundingObject USE shape
      physics Physics {
      }
      rotationStep 0.2
      recognitionColors [
        0 0 1
      ]
      type "sonar"
      numberOfRays 20
    }
    DistanceSensor {
      translation -0.094 -0.063 0.063
      rotation -9.654262932951822e-10 1.9640889282456528e-08 -0.9999999999999998 2.5252996938995746
      children [
        DEF shape Shape {
          appearance PBRAppearance {
          }
          geometry Box {
            size 0.01 0.01 0.01
          }
        }
      ]
      name "left_sensor"
      boundingObject USE shape
      physics Physics {
      }
      type "sonar"
      numberOfRays 20
    }
    DistanceSensor {
      translation -0.094 0.02 0.064
      rotation 4.881972694376839e-09 1.9048960880375854e-08 0.9999999999999999 2.3944003061004255
      children [
        DEF shape Shape {
          appearance PBRAppearance {
          }
          geometry Box {
            size 0.01 0.01 0.01
          }
        }
      ]
      name "right sensor"
      boundingObject USE shape
      physics Physics {
      }
      type "sonar"
      numberOfRays 20
      resolution 0.001
    }
    HingeJoint {
      jointParameters HingeJointParameters {
        position -567.9801240135486
        axis 0 1 0
        anchor -0.05 0.035 0.05
      }
      device [
        RotationalMotor {
          name "wheel1"
        }
      ]
      endPoint Solid {
        translation -0.05000615501368271 0.034999952562175876 0.050002296869845385
        rotation -0.23109902654526734 0.6879644077634907 -0.6879667241810896 3.595815068577054
        children [
          DEF wheel Shape {
            appearance Appearance {
              material Material {
                diffuseColor 0.1 0.1 0.1
              }
            }
            geometry Cylinder {
              height 0.02
              radius 0.04
            }
          }
        ]
        name "right front wheel"
        boundingObject USE wheel
        physics Physics {
        }
        linearVelocity 0.24955517135643648 -0.02885818711381378 -1.7481031407591992e-05
        angularVelocity 0.7215498491881389 6.23867026148106 0.00827569851996983
      }
    }
    HingeJoint {
      jointParameters HingeJointParameters {
        position 3047.6764479896774
        axis 0 1 0
        anchor 0.07 0.036 0.05
      }
      device [
        RotationalMotor {
          name "wheel2"
        }
      ]
      endPoint Solid {
        translation 0.06999687725964425 0.03599995256164547 0.04999421986337426
        rotation -0.97312660677251 -0.1628257176554959 0.1628262658829757 4.685147897736961
        children [
          DEF wheel Shape {
            appearance Appearance {
              material Material {
                diffuseColor 0.1 0.1 0.1
              }
            }
            geometry Cylinder {
              height 0.02
              radius 0.04
            }
          }
        ]
        name "right rear wheel"
        boundingObject USE wheel
        physics Physics {
        }
        linearVelocity 0.24953466744491837 -0.02886037359006154 2.546653755906116e-05
        angularVelocity 0.7215499721599474 6.238668632673079 0.008275490603835943
      }
    }
    HingeJoint {
      jointParameters HingeJointParameters {
        position -3286.6060422958426
        axis 0 1 0
        anchor -0.05 -0.084 0.05
      }
      device [
        RotationalMotor {
          name "wheel3"
        }
      ]
      endPoint Solid {
        translation -0.04999666442204799 -0.08400004743782703 0.05000497749994888
        rotation -0.9405263861867657 0.24021829405352385 -0.24021925003728894 4.651107817686313
        children [
          DEF wheel Shape {
            appearance Appearance {
              material Material {
                diffuseColor 0.1 0.1 0.1
              }
            }
            geometry Cylinder {
              height 0.02
              radius 0.04
            }
          }
        ]
        name "left front wheel"
        boundingObject USE wheel
        physics Physics {
        }
        linearVelocity 0.24954065247236734 -0.028861972648843152 1.1542837046306876e-05
        angularVelocity 0.7215498910385518 6.23866913415909 0.008275894073623431
      }
    }
    HingeJoint {
      jointParameters HingeJointParameters {
        position 303.85131221167075
        axis 0 1 0
        anchor 0.07 -0.08 0.05
      }
      device [
        RotationalMotor {
          name "wheel4"
        }
      ]
      endPoint Solid {
        translation 0.06999365856924267 -0.0800000474383573 0.05000386028795131
        rotation 0.3170229840218475 0.6706315675612946 -0.6706338257142747 2.5275943349651655
        children [
          DEF wheel Shape {
            appearance Appearance {
              material Material {
                diffuseColor 0.1 0.1 0.1
              }
            }
            geometry Cylinder {
              height 0.02
              radius 0.04
            }
          }
        ]
        name "left rear wheel"
        boundingObject USE wheel
        physics DEF Physics_wheel Physics {
        }
        linearVelocity 0.24955751470380697 -0.028867568014172028 -1.94347439423515e-05
        angularVelocity 0.721550316993913 6.238670480951769 0.008275647552649121
      }
    }
    Solid {
      translation 0.01000004705669814 -0.02300045029615594 0.05966096755460201
      rotation 0.09774185760042062 0.9952115167835832 -0.0007524188587491342 5.873696995880097e-09
      children [
        DEF body Shape {
          appearance Appearance {
            material Material {
              diffuseColor 0 0.666667 0
            }
          }
          geometry Box {
            size 0.2 0.1 0.05
          }
        }
      ]
      name "base"
      boundingObject USE body
      physics Physics {
      }
    }
  ]
  name "Mobile"
  physics Physics {
  }
  controller "mobile_controller"
  linearVelocity 0.2495313429354044 -0.028865297823895464 2.0792798254318928e-05
  angularVelocity -0.0002618292359498816 0.00029470530611452146 0.00015143619028564764
}
